Workbook

Sheet Measurements
A1: pair | B1: file | C1: VOT (ms) | D1: file dur (ms) | E1: vowel onset (s) | F1: vowel dur (ms) | G1: f0 onset mean (Hz) | H1: f0 mean (Hz) | I1: f0 median (Hz) | J1: f0 min (Hz) | K1: f0 max (Hz) | L1: f0 SD (Hz) | M1: f0_1 | N1: f0_2 | O1: f0_3 | P1: f0_4 | Q1: f0_5 | R1: f0_6 | S1: f0_7 | T1: f0_8 | U1: f0_9 | V1: f0_10
A2: dill_till | B2: dill_-100 | C2: -100 | D2: 338.75 | E2: 0.03 | F2: 225 | G2: 101.8 | H2: 98.7 | I2: 97.66 | J2: 96.77 | K2: 104 | L2: 2.01 | M2: 103.69 | N2: 103.39 | O2: 103.06 | P2: 102.43 | Q2: 101.83 | R2: 101.4 | S2: 100.99 | T2: 100.73 | U2: 100.44 | V2: 100.04
A3: dill_till | B3: dill_-50 | C3: -50 | D3: 388.75 | E3: 0.055 | F3: 250 | G3: 103.75 | H3: 99.3 | I3: 97.67 | J3: 96.77 | K3: 105.73 | L3: 2.67 | M3: 105.29 | N3: 104.87 | O3: 104.6 | P3: 104.31 | Q3: 104 | R3: 103.69 | S3: 103.39 | T3: 103.06 | U3: 102.43 | V3: 101.83
A4: dill_till | B4: dill_-20 | C4: -20 | D4: 358.75 | E4: 0.035 | F4: 240 | G4: 102.97 | H4: 99.06 | I4: 97.66 | J4: 96.77 | K4: 104.87 | L4: 2.41 | M4: 104.59 | N4: 104.31 | O4: 104 | P4: 103.69 | Q4: 103.39 | R4: 103.06 | S4: 102.43 | T4: 101.83 | U4: 101.4 | V4: 100.99
A5: dill_till | B5: dill_-15 | C5: -15 | D5: 353.74 | E5: 0.03 | F5: 240 | G5: 103.02 | H5: 99.07 | I5: 97.76 | J5: 96.82 | K5: 104.94 | L5: 2.43 | M5: 104.62 | N5: 104.32 | O5: 104 | P5: 103.66 | Q5: 103.37 | R5: 103.12 | S5: 102.63 | T5: 101.99 | U5: 101.48 | V5: 101.04
A6: dill_till | B6: dill_-10 | C6: -10 | D6: 348.75 | E6: 0.035 | F6: 230 | G6: 102.2 | H6: 98.81 | I6: 97.66 | J6: 96.77 | K6: 104.31 | L6: 2.15 | M6: 104 | N6: 103.69 | O6: 103.39 | P6: 103.06 | Q6: 102.43 | R6: 101.83 | S6: 101.4 | T6: 100.99 | U6: 100.73 | V6: 100.44
A7: dill_till | B7: dill_-5 | C7: -5 | D7: 343.76 | E7: 0.035 | F7: 225 | G7: 101.85 | H7: 98.71 | I7: 97.68 | J7: 96.82 | K7: 104 | L7: 2.03 | M7: 103.66 | N7: 103.38 | O7: 103.12 | P7: 102.63 | Q7: 101.99 | R7: 101.48 | S7: 101.04 | T7: 100.69 | U7: 100.39 | V7: 100.06
A8: dill_till | B8: dill_0 | C8: 0 | D8: 338.75 | E8: 0.03 | F8: 225 | G8: 101.8 | H8: 98.7 | I8: 97.66 | J8: 96.77 | K8: 104 | L8: 2.01 | M8: 103.69 | N8: 103.39 | O8: 103.06 | P8: 102.43 | Q8: 101.83 | R8: 101.4 | S8: 100.99 | T8: 100.73 | U8: 100.44 | V8: 100.04
A9: dill_till | B9: dill_5 | C9: 5 | D9: 338.73 | E9: 0.03 | F9: 225 | G9: 101.93 | H9: 98.72 | I9: 97.7 | J9: 96.86 | K9: 104.19 | L9: 2.08 | M9: 103.92 | N9: 103.7 | O9: 103.41 | P9: 102.59 | Q9: 101.82 | R9: 101.44 | S9: 101.07 | T9: 100.79 | U9: 100.49 | V9: 100.07
A10: dill_till | B10: dill_10 | C10: 10 | D10: 343.11 | E10: 0.035 | F10: 220 | G10: 101.87 | H10: 98.73 | I10: 97.71 | J10: 96.9 | K10: 104.36 | L10: 2.08 | M10: 104.08 | N10: 103.58 | O10: 102.97 | P10: 102.43 | Q10: 101.91 | R10: 101.54 | S10: 101.24 | T10: 100.79 | U10: 100.26 | V10: 99.88
A11: dill_till | B11: dill_15 | C11: 15 | D11: 346.44 | E11: 0.03 | F11: 230 | G11: 102.98 | H11: 99.04 | I11: 97.78 | J11: 96.89 | K11: 105.31 | L11: 2.48 | M11: 104.98 | N11: 104.6 | O11: 104.24 | P11: 103.89 | Q11: 103.42 | R11: 102.72 | S11: 102.13 | T11: 101.72 | U11: 101.28 | V11: 100.79
A12: dill_till | B12: dill_20 | C12: 20 | D12: 349.82 | E12: 0.035 | F12: 230 | G12: 103 | H12: 99.02 | I12: 97.7 | J12: 96.86 | K12: 105.45 | L12: 2.51 | M12: 105.08 | N12: 104.71 | O12: 104.43 | P12: 104.15 | Q12: 103.38 | R12: 102.61 | S12: 102.08 | T12: 101.54 | U12: 101.19 | V12: 100.83
A13: dill_till | B13: dill_25 | C13: 25 | D13: 353.15 | E13: 0.03 | F13: 235 | G13: 103.77 | H13: 99.28 | I13: 97.73 | J13: 96.9 | K13: 106.28 | L13: 2.79 | M13: 105.93 | N13: 105.43 | O13: 105.08 | P13: 104.8 | Q13: 104.24 | R13: 103.54 | S13: 102.94 | T13: 102.39 | U13: 101.91 | V13: 101.48
... A15: dill_till | B15: dill_35 | C15: 35 | D15: 359.84 | E15: 0.035 | F15: 235 | G15: 104.55 | H15: 99.49 | I15: 97.72 | J15: 96.77 | K15: 107.1 | L15: 3.11 | M15: 106.66 | N15: 106.22 | O15: 105.82 | P15: 105.42 | Q15: 105.11 | R15: 104.8 | S15: 103.94 | T15: 103.08 | U15: 102.52 | V15: 101.95
A16: dill_till | B16: dill_40 | C16: 40 | D16: 363.2 | E16: 0.03 | F16: 245 | G16: 105.31 | H16: 99.57 | I16: 97.73 | J16: 96.9 | K16: 107.06 | L16: 3.22 | N16: 107.06 | O16: 106.83 | P16: 106.5 | Q16: 106.09 | R16: 105.65 | S16: 104.99 | T16: 104.24 | U16: 103.55 | V16: 102.89
A17: dill_till | B17: dill_45 | C17: 45 | D17: 366.55 | E17: 0.04 | F17: 240 | G17: 105.1 | H17: 99.46 | I17: 97.77 | J17: 96.78 | K17: 106.93 | L17: 3.13 | N17: 106.93 | O17: 106.79 | P17: 106.36 | Q17: 105.84 | R17: 105.14 | S17: 104.49 | T17: 103.93 | U17: 103.42 | V17: 103.02
A18: dill_till | B18: dill_50 | C18: 50 | D18: 369.91 | E18: 0.04 | F18: 240 | G18: 105.73 | H18: 99.62 | I18: 97.72 | J18: 96.9 | K18: 107.21 | L18: 3.31 | N18: 107.21 | O18: 107.2 | P18: 106.83 | Q18: 106.46 | R18: 106.01 | S18: 105.56 | T18: 104.79 | U18: 104.02 | V18: 103.44
A19: dill_till | B19: dill_55 | C19: 55 | D19: 373.24 | E19: 0.045 | F19: 240 | G19: 105.43 | H19: 99.49 | I19: 97.71 | J19: 96.86 | K19: 107.31 | L19: 3.23 | O19: 107.31 | P19: 107.03 | Q19: 106.61 | R19: 105.95 | S19: 105.17 | T19: 104.44 | U19: 103.72 | V19: 103.19
A20: dill_till | B20: dill_60 | C20: 60 | D20: 376.6 | E20: 0.05 | F20: 240 | G20: 105.8 | H20: 99.61 | I20: 97.68 | J20: 96.79 | K20: 107.71 | L20: 3.41 | N20: 107.71 | O20: 107.59 | P20: 107.24 | Q20: 106.74 | R20: 105.94 | S20: 105.18 | T20: 104.52 | U20: 103.89 | V20: 103.34
A21: dill_till | B21: dill_65 | C21: 65 | D21: 379.95 | E21: 0.06 | F21: 230 | G21: 105.63 | H21: 99.79 | I21: 97.75 | J21: 96.88 | K21: 108.13 | L21: 3.61 | M21: 108.13 | N21: 107.71 | O21: 107.3 | P21: 106.76 | Q21: 106.22 | R21: 105.45 | S21: 104.68 | T21: 103.99 | U21: 103.3 | V21: 102.71
A22: dill_till | B22: dill_70 | C22: 70 | D22: 383.31 | E22: 0.065 | F22: 230 | G22: 105.56 | H22: 99.69 | I22: 97.7 | J22: 96.86 | K22: 107.97 | L22: 3.56 | M22: 107.97 | N22: 107.86 | O22: 107.69 | P22: 107.03 | Q22: 106.13 | R22: 105.19 | S22: 104.22 | T22: 103.63 | U22: 103.22 | V22: 102.67
A23: dill_till | B23: dill_75 | C23: 75 | D23: 386.64 | E23: 0.065 | F23: 235 | G23: 105.88 | H23: 99.54 | I23: 97.71 | J23: 96.77 | K23: 107.91 | L23: 3.38 | O23: 107.91 | P23: 107.7 | Q23: 107.06 | R23: 106.35 | S23: 105.46 | T23: 104.71 | U23: 104.21 | V23: 103.65
A24: dill_till | B24: dill_80 | C24: 80 | D24: 390 | E24: 0.07 | F24: 230 | G24: 106.26 | H24: 99.89 | I24: 97.73 | J24: 96.76 | K24: 108.19 | L24: 3.78 | N24: 108.19 | O24: 108.13 | P24: 108.08 | Q24: 107.3 | R24: 106.51 | S24: 105.54 | T24: 104.57 | U24: 104.21 | V24: 103.84
A25: dill_till | B25: dill_85 | C25: 85 | D25: 393.36 | E25: 0.075 | F25: 230 | G25: 106.57 | H25: 100 | I25: 97.71 | J25: 96.83 | K25: 108.73 | L25: 3.96 | M25: 108.73 | N25: 108.72 | O25: 108.7 | P25: 108.11 | Q25: 107.22 | R25: 106.28 | S25: 105.3 | T25: 104.7 | U25: 104.3 | V25: 103.62
A26: dill_till | B26: dill_90 | C26: 90 | D26: 396.71 | E26: 0.08 | F26: 230 | G26: 106.46 | H26: 99.74 | I26: 97.72 | J26: 96.84 | K26: 109.06 | L26: 3.75 | N26: 109.06 | O26: 108.8 | P26: 108.04 | Q26: 107.22 | R26: 106.32 | S26: 105.55 | T26: 105.07 | U26: 104.48 | V26: 103.63
A27: dill_till | B27: dill_95 | C27: 95 | D27: 400.05 | E27: 0.09 | F27: 230 | G27: 105.77 | H27: 99.58 | I27: 97.7 | J27: 96.87 | K27: 108.71 | L27: 3.63 | N27: 108.71 | O27: 108.1 | P27: 107.48 | Q27: 106.48 | R27: 105.48 | S27: 104.98 | T27: 104.47 | U27: 103.55 | V27: 102.62
A28: dill_till | B28: dill_100 | C28: 100 | D28: 403.4 | E28: 0.09 | F28: 235 | G28: 106.4 | H28: 99.69 | I28: 97.7 | J28: 96.8 | K28: 108.86 | L28: 3.78 | N28: 108.86 | O28: 108.61 | P28: 108.24 | Q28: 107.37 | R28: 106.23 | S28: 105.55 | T28: 105.11 | U28: 104.3 | V28: 103.32
A29: dill_till | B29: dill_105 | C29: 105 | D29: 406.76 | E29: 0.095 | F29: 230 | G29: 106.49 | H29: 99.65 | I29: 97.67 | J29: 96.85 | K29: 108.72 | L29: 3.65 | O29: 108.72 | P29: 108.41 | Q29: 107.47 | R29: 106.67 | S29: 106.18 | T29: 105.6 | U29: 104.84 | V29: 104.05
A30: dill_till | B30: dill_110 | C30: 110 | D30: 410.11 | E30: 0.1 | F30: 230 | G30: 106.98 | H30: 100.03 | I30: 97.75 | J30: 96.88 | K30: 109.47 | L30: 4.1 | N30: 109.47 | O30: 109.04 | P30: 108.61 | Q30: 107.86 | R30: 107.11 | S30: 106.28 | T30: 105.45 | U30: 104.82 | V30: 104.19
A31: dill_till | B31: dill_115 | C31: 115 | D31: 413.45 | E31: 0.11 | F31: 225 | G31: 106.6 | H31: 99.95 | I31: 97.73 | J31: 96.86 | K31: 110.15 | L31: 4.15 | M31: 109.83 | N31: 109.34 | O31: 108.6 | P31: 107.73 | Q31: 107.06 | R31: 106.49 | S31: 105.66 | T31: 104.71 | U31: 103.75 | V31: 102.79
A32: dill_till | B32: dill_120 | C32: 120 | D32: 416.8 | E32: 0.115 | F32: 220 | G32: 106.55 | H32: 99.81 | I32: 97.71 | J32: 96.85 | K32: 109.72 | L32: 4.01 | M32: 109.72 | N32: 109.51 | O32: 108.83 | P32: 108.01 | Q32: 106.88 | R32: 105.96 | S32: 105.47 | T32: 104.79 | U32: 103.68 | V32: 102.63
A33: dill_till | B33: dill_125 | C33: 125 | D33: 420.14 | E33: 0.12 | F33: 220 | G33: 106.32 | H33: 99.76 | I33: 97.65 | J33: 96.84 | K33: 109.63 | L33: 3.96 | N33: 109.63 | O33: 108.96 | P33: 108.28 | Q33: 107.2 | R33: 106.12 | S33: 105.48 | T33: 104.84 | U33: 103.72 | V33: 102.61
A34: dill_till | B34: dill_130 | C34: 130 | D34: 423.51 | E34: 0.125 | F34: 215 | G34: 106.72 | H34: 99.96 | I34: 97.73 | J34: 96.78 | K34: 110.13 | L34: 4.21 | M34: 110.13 | N34: 109.76 | O34: 109.18 | P34: 108.24 | Q34: 107.11 | R34: 106.28 | S34: 105.61 | T34: 104.68 | U34: 103.61 | V34: 102.58
A35: din_tin | B35: din_-100 | C35: -100 | D35: 424.92 | E35: 0.1 | F35: 160 | G35: 105.08 | H35: 101.71 | I35: 100.24 | J35: 99.15 | K35: 107.14 | L35: 2.75 | M35: 106.98 | N35: 106.67 | O35: 106.29 | P35: 105.85 | Q35: 105.42 | R35: 104.99 | S35: 104.47 | T35: 103.88 | U35: 103.35 | V35: 102.88
A36: din_tin | B36: din_-50 | C36: -50 | D36: 374.92 | E36: 0.05 | F36: 160 | G36: 105.07 | H36: 101.71 | I36: 100.24 | J36: 99.15 | K36: 107.05 | L36: 2.74 | M36: 106.91 | N36: 106.65 | O36: 106.29 | P36: 105.86 | Q36: 105.42 | R36: 104.99 | S36: 104.47 | T36: 103.88 | U36: 103.35 | V36: 102.87
A37: din_tin | B37: din_-20 | C37: -20 | D37: 344.92 | E37: 0.03 | F37: 150 | G37: 104.15 | H37: 101.36 | I37: 99.93 | J37: 99.15 | K37: 106.65 | L37: 2.44 | M37: 106.29 | N37: 105.85 | O37: 105.42 | P37: 104.99 | Q37: 104.47 | R37: 103.88 | S37: 103.35 | T37: 102.88 | U37: 102.4 | V37: 101.92
A38: din_tin | B38: din_-15 | C38: -15 | D38: 339.93 | E38: 0.03 | F38: 145 | G38: 103.65 | H38: 101.18 | I38: 99.87 | J38: 99.16 | K38: 106.29 | L38: 2.28 | M38: 105.87 | N38: 105.44 | O38: 105.01 | P38: 104.38 | Q38: 103.76 | R38: 103.4 | S38: 103.04 | T38: 102.44 | U38: 101.85 | V38: 101.35
A39: din_tin | B39: din_-10 | C39: -10 | D39: 334.92 | E39: 0.035 | F39: 135 | G39: 102.64 | H39: 100.84 | I39: 99.81 | J39: 99.15 | K39: 105.42 | L39: 1.93 | M39: 104.99 | N39: 104.47 | O39: 103.88 | P39: 103.35 | Q39: 102.87 | R39: 102.4 | S39: 101.92 | T39: 101.39 | U39: 100.83 | V39: 100.32
A40: din_tin | B40: din_-5 | C40: -5 | D40: 329.93 | E40: 0.03 | F40: 135 | G40: 102.64 | H40: 100.83 | I40: 99.85 | J40: 99.16 | K40: 105.44 | L40: 1.93 | M40: 105.01 | N40: 104.38 | O40: 103.76 | P40: 103.4 | Q40: 103.04 | R40: 102.44 | S40: 101.85 | T40: 101.35 | U40: 100.86 | V40: 100.3
A41: din_tin | B41: din_0 | C41: 0 | D41: 324.92 | E41: 0.035 | F41: 125 | G41: 101.64 | H41: 100.5 | I41: 99.76 | J41: 99.15 | K41: 104.47 | L41: 1.55 | M41: 103.88 | N41: 103.35 | O41: 102.87 | P41: 102.4 | Q41: 101.92 | R41: 101.39 | S41: 100.83 | T41: 100.32 | U41: 99.86 | V41: 99.57
...

Sheet Summary
A1: Per-continuum summary (formulas reference the Measurements sheet)
A3: continuum | B3: n files | C3: VOT range (ms) | D3: mean file dur (ms) | E3: mean vowel dur (ms) | F3: mean f0 onset (Hz) | G3: min f0 onset | H3: max f0 onset | I3: mean f0 (Hz) | J3: min f0 mean | K3: max f0 mean
A4: dill_till | B4: =COUNTIF(Measurements!$A$2:$A$100,"dill_till") -> 33 | C4: -100 to 130 | D4: =AVERAGEIF(Measurements!$A$2:$A$100,"dill_till",Measurements!$D$2:$D$100) -> 375.53152 | E4: =AVERAGEIF(Measurements!$A$2:$A$100,"dill_till",Measurements!$F$2:$F$100) -> 231.51515 | F4: =AVERAGEIF(Measurements!$A$2:$A$100,"dill_till",Measurements!$G$2:$G$100) -> 104.69515 | G4: =_xlfn.MINIFS(Measurements!$G$2:$G$100,Measurements!$A$2:$A$100,"dill_till") -> 101.8 | H4: =_xlfn.MAXIFS(Measurements!$G$2:$G$100,Measurements!$A$2:$A$100,"dill_till") -> 106.98 | I4: =AVERAGEIF(Measurements!$A$2:$A$100,"dill_till",Measurements!$H$2:$H$100) -> 99.416667 | J4: =_xlfn.MINIFS(Measurements!$H$2:$H$100,Measurements!$A$2:$A$100,"dill_till") -> 98.7 | K4: =_xlfn.MAXIFS(Measurements!$H$2:$H$100,Measurements!$A$2:$A$100,"dill_till") -> 100.03
A5: din_tin | B5: =COUNTIF(Measurements!$A$2:$A$100,"din_tin") -> 33 | C5: -100 to 130 | D5: =AVERAGEIF(Measurements!$A$2:$A$100,"din_tin",Measurements!$D$2:$D$100) -> 364.73697 | E5: =AVERAGEIF(Measurements!$A$2:$A$100,"din_tin",Measurements!$F$2:$F$100) -> 151.66667 | F5: =AVERAGEIF(Measurements!$A$2:$A$100,"din_tin",Measurements!$G$2:$G$100) -> 106.02545 | G5: =_xlfn.MINIFS(Measurements!$G$2:$G$100,Measurements!$A$2:$A$100,"din_tin") -> 101.64 | H5: =_xlfn.MAXIFS(Measurements!$G$2:$G$100,Measurements!$A$2:$A$100,"din_tin") -> 109.75 | I5: =AVERAGEIF(Measurements!$A$2:$A$100,"din_tin",Measurements!$H$2:$H$100) -> 102.1197 | J5: =_xlfn.MINIFS(Measurements!$H$2:$H$100,Measurements!$A$2:$A$100,"din_tin") -> 100.5 | K5: =_xlfn.MAXIFS(Measurements!$H$2:$H$100,Measurements!$A$2:$A$100,"din_tin") -> 104.05
A6: dip_tip | B6: =COUNTIF(Measurements!$A$2:$A$100,"dip_tip") -> 33 | C6: -100 to 130 | D6: =AVERAGEIF(Measurements!$A$2:$A$100,"dip_tip",Measurements!$D$2:$D$100) -> 435.09061 | E6: =AVERAGEIF(Measurements!$A$2:$A$100,"dip_tip",Measurements!$F$2:$F$100) -> 114.24242 | F6: =AVERAGEIF(Measurements!$A$2:$A$100,"dip_tip",Measurements!$G$2:$G$100) -> 104.15879 | G6: =_xlfn.MINIFS(Measurements!$G$2:$G$100,Measurements!$A$2:$A$100,"dip_tip") -> 101.46 | H6: =_xlfn.MAXIFS(Measurements!$G$2:$G$100,Measurements!$A$2:$A$100,"dip_tip") -> 107.2 | I6: =AVERAGEIF(Measurements!$A$2:$A$100,"dip_tip",Measurements!$H$2:$H$100) -> 103.18152 | J6: =_xlfn.MINIFS(Measurements!$H$2:$H$100,Measurements!$A$2:$A$100,"dip_tip") -> 101.67 | K6: =_xlfn.MAXIFS(Measurements!$H$2:$H$100,Measurements!$A$2:$A$100,"dip_tip") -> 105.69

Sheet Notes & Method
A1: Cue analysis of d–t VOT-continuum stimuli
A3: Source stimuli: stimuli/d-t/{dill_till, din_tin, dip_tip}/!final VOT continuum_selected_70dBnormed/ (33 files each, 99 total).
A4: Analysis adapted from data/Chodroff2017/cueAnalysis_engCVC.praat.
A6: Why the original script could not be run directly:
A7: The Chodroff script reads stop-release and vowel boundaries from paired *_autovot.TextGrid files and measures VOT / sonorant duration / F0 from those intervals. These continuum folders contain only .wav files (no TextGrids), so the boundary-dependent steps have nothing to read. The measurement logic was therefore re-implemented on the waveforms using Praat's own engine (parselmouth).
A9: How each value was obtained:
A10: VOT (ms): taken from the number encoded in each filename — the designed continuum step. Negative = voicing lead / prevoicing, positive = long-lag (aspiration).
A11: file dur (ms): total duration of the .wav file. It is V-shaped in VOT (minimum near VOT = 0) because prevoicing or aspiration is prepended before the shared vowel, so more |VOT| = a longer file.
A12: vowel onset / vowel dur: the vocalic nucleus is located by an intensity threshold (within 10 dB of each file's intensity peak, sustained ≥ 25 ms). This one rule works for the /l/, /n/ and /p/ codas and for both prevoiced and aspirated tokens. Without hand-corrected TextGrids these boundaries are estimates, not gold-standard.
A13: F0: Praat 'To Pitch... 0.0 75 600' (floor 75 Hz, ceiling 600 Hz), exactly as in the original script. f0_1..f0_10 are F0 sampled every 5 ms across the first 50 ms of the vowel (Chodroff-style); f0 onset mean is their average; f0 mean/median/min/max/SD summarize the whole vowel nucleus.
A15: Data-quality flags:
A16: • dill_-100.wav is byte-for-byte identical to dill_0.wav (same MD5, same 338.75 ms duration). It is a duplicate / placeholder, NOT a true -100 ms prevoiced token. In din_tin and dip_tip the -100 files are correctly the longest in the set. Recommend re-rendering dill_-100. Its row is included but its acoustics equal dill_0.
... A18: • Vowel-onset F0 rises modestly with VOT (~101 → 107-109 Hz). Part of this is the expected voiceless-stop f0-raising micro-pattern; part is that longer aspiration masks the earliest (lower-F0) part of the vowel, so the first voiced sample falls later.
